<mujoco model="hithand">
    <compiler angle="radian" meshdir="meshes/" />
    <size njmax="500" nconmax="100" />
    <asset>
        <mesh name="hit-hand-2-palm-right" file="hit-hand-2-palm-right.stl" />
        <mesh name="hit-hand-2-finger-basecover" file="hit-hand-2-finger-basecover.stl" />
        <mesh name="hit-hand-2-finger-phaprox" file="hit-hand-2-finger-phaprox.stl" />
        <mesh name="hit-hand-2-finger-phamed" file="hit-hand-2-finger-phamed.stl" />
        <mesh name="hit-hand-2-finger-phadist" file="hit-hand-2-finger-phadist.stl" />
    </asset>
    <worldbody>
        <geom type="mesh" mesh="hit-hand-2-palm-right" />
        <body name="Right_Thumb_Basecover" pos="0.0621759 0.0443729 0.0787348" quat="0.821503 0.199145 -0.481905 0.230741">
            <inertial pos="0 0 0" mass="1" diaginertia="1 1 1" />
            <joint name="Right_Thumb_1" pos="0 0 0" axis="0 0 1" limited="true" range="-0.5 1.4" damping="0.7" frictionloss="0.5" />
            <geom type="mesh" mesh="hit-hand-2-finger-basecover" />
            <body name="Right_Thumb_Phoaprox" pos="0 0 0" quat="0.707105 0.707108 0 0">
                <inertial pos="0.0621759 0.0443729 0.0787348" quat="0.821503 0.199145 -0.481905 0.230741" mass="1" diaginertia="1 1 1" />
                <joint name="Right_Thumb_2" pos="0 0 0" axis="0 0 1" limited="true" range="-0.5 1.4" damping="0.7" frictionloss="0.5" />
                <geom pos="0 0 0" type="mesh" mesh="hit-hand-2-finger-phaprox" />
                <body name="Right_Thumb_Phamed" pos="0.055 0 0">
                    <inertial pos="0 0 0" mass="1" diaginertia="1 1 1" />
                    <joint name="Right_Thumb_3" pos="0 0 0" axis="0 0 1" limited="true" range="-0.5 1.4" damping="0.7" frictionloss="0.5" />
                    <geom pos="0.01 0 0" type="mesh" mesh="hit-hand-2-finger-phamed" />
                    <body name="Right_Thumb_Phadist" pos="0.025 0 0" quat="0.707388 0 0 -0.706825">
                        <inertial pos="0 0 0" mass="1" diaginertia="1 1 1" />
                        <joint name="Right_Thumb_4" pos="0 0 0" axis="0 0 1" limited="true" range="-0.5 1.4" damping="0.7" frictionloss="0.5" />
                        <geom type="mesh" mesh="hit-hand-2-finger-phadist" />
                    </body>
                </body>
            </body>
        </body>
        <body name="Right_Index_Basecover" pos="-0.00252988 0.0368001 0.107784" quat="0.0308436 0.706434 -0.0308436 0.706434">
            <inertial pos="0 0 0" mass="1" diaginertia="1 1 1" />
            <joint name="Right_Index_1" pos="0 0 0" axis="0 0 1" limited="true" range="-0.5 1.4" damping="0.7" frictionloss="0.5" />
            <geom type="mesh" mesh="hit-hand-2-finger-basecover" />
            <body name="Right_Index_Phoaprox" pos="0 0 0" quat="0.707105 0.707108 0 0">
                <inertial pos="0.0621759 0.0443729 0.0787348" quat="0.821503 0.199145 -0.481905 0.230741" mass="1" diaginertia="1 1 1" />
                <joint name="Right_Index_2" pos="0 0 0" axis="0 0 1" limited="true" range="-0.5 1.4" damping="0.7" frictionloss="0.5" />
                <geom pos="0 0 0" type="mesh" mesh="hit-hand-2-finger-phaprox" />
                <body name="Right_Index_Phamed" pos="0.055 0 0">
                    <inertial pos="0 0 0" mass="1" diaginertia="1 1 1" />
                    <joint name="Right_Index_3" pos="0 0 0" axis="0 0 1" limited="true" range="-0.5 1.4" damping="0.7" frictionloss="0.5" />
                    <geom pos="0.01 0 0" type="mesh" mesh="hit-hand-2-finger-phamed" />
                    <body name="Right_Index_Phadist" pos="0.025 0 0" quat="0.707388 0 0 -0.706825">
                        <inertial pos="0 0 0" mass="1" diaginertia="1 1 1" />
                        <joint name="Right_Index_4" pos="0 0 0" axis="0 0 1" limited="true" range="-0.5 1.4" damping="0.7" frictionloss="0.5" />
                        <geom type="mesh" mesh="hit-hand-2-finger-phadist" />
                    </body>
                </body>
            </body>
        </body>
        <body name="Right_Middle_Basecover" pos="-0.0037 0.01 0.117784" quat="-1.22475e-07 -0.707107 1.22474e-07 -0.707107">
            <inertial pos="0 0 0" mass="1" diaginertia="1 1 1" />
            <joint name="Right_Middle_1" pos="0 0 0" axis="0 0 1" limited="true" range="-0.5 1.4" damping="0.7" frictionloss="0.5" />
            <geom type="mesh" mesh="hit-hand-2-finger-basecover" />
            <body name="Right_Middle_Phoaprox" pos="0 0 0" quat="0.707105 0.707108 0 0">
                <inertial pos="0.0621759 0.0443729 0.0787348" quat="0.821503 0.199145 -0.481905 0.230741" mass="1" diaginertia="1 1 1" />
                <joint name="Right_Middle_2" pos="0 0 0" axis="0 0 1" limited="true" range="-0.5 1.4" damping="0.7" frictionloss="0.5" />
                <geom pos="0 0 0" type="mesh" mesh="hit-hand-2-finger-phaprox" />
                <body name="Right_Middle_Phamed" pos="0.055 0 0">
                    <inertial pos="0 0 0" mass="1" diaginertia="1 1 1" />
                    <joint name="Right_Middle_3" pos="0 0 0" axis="0 0 1" limited="true" range="-0.5 1.4" damping="0.7" frictionloss="0.5" />
                    <geom pos="0.01 0 0" type="mesh" mesh="hit-hand-2-finger-phamed" />
                    <body name="Right_Middle_Phadist" pos="0.025 0 0" quat="0.707388 0 0 -0.706825">
                        <inertial pos="0 0 0" mass="1" diaginertia="1 1 1" />
                        <joint name="Right_Middle_4" pos="0 0 0" axis="0 0 1" limited="true" range="-0.5 1.4" damping="0.7" frictionloss="0.5" />
                        <geom type="mesh" mesh="hit-hand-2-finger-phadist" />
                    </body>
                </body>
            </body>
        </body>
        <body name="Right_Ring_Basecover" pos="0 -0.0168001 0.112584" quat="0.0308436 -0.706434 -0.0308436 -0.706434">
            <inertial pos="0 0 0" mass="1" diaginertia="1 1 1" />
            <joint name="Right_Ring_1" pos="0 0 0" axis="0 0 1" limited="true" range="-0.5 1.4" damping="0.7" frictionloss="0.5" />
            <geom type="mesh" mesh="hit-hand-2-finger-basecover" />
            <body name="Right_Ring_Phoaprox" pos="0 0 0" quat="0.707105 0.707108 0 0">
                <inertial pos="0.0621759 0.0443729 0.0787348" quat="0.821503 0.199145 -0.481905 0.230741" mass="1" diaginertia="1 1 1" />
                <joint name="Right_Ring_2" pos="0 0 0" axis="0 0 1" limited="true" range="-0.5 1.4" damping="0.7" frictionloss="0.5" />
                <geom pos="0 0 0" type="mesh" mesh="hit-hand-2-finger-phaprox" />
                <body name="Right_Ring_Phamed" pos="0.055 0 0">
                    <inertial pos="0 0 0" mass="1" diaginertia="1 1 1" />
                    <joint name="Right_Ring_3" pos="0 0 0" axis="0 0 1" limited="true" range="-0.5 1.4" damping="0.7" frictionloss="0.5" />
                    <geom pos="0.01 0 0" type="mesh" mesh="hit-hand-2-finger-phamed" />
                    <body name="Right_Ring_Phadist" pos="0.025 0 0" quat="0.707388 0 0 -0.706825">
                        <inertial pos="0 0 0" mass="1" diaginertia="1 1 1" />
                        <joint name="Right_Ring_4" pos="0 0 0" axis="0 0 1" limited="true" range="-0.5 1.4" damping="0.7" frictionloss="0.5" />
                        <geom type="mesh" mesh="hit-hand-2-finger-phadist" />
                    </body>
                </body>
            </body>
        </body>
        <body name="Right_Little_Basecover" pos="0.000971571 -0.0433963 0.0935835" quat="0.0616283 -0.704416 -0.0616283 -0.704416">
            <inertial pos="0 0 0" mass="1" diaginertia="1 1 1" />
            <joint name="Right_Little_1" pos="0 0 0" axis="0 0 1" limited="true" range="-0.5 1.4" damping="0.7" frictionloss="0.5" />
            <geom type="mesh" mesh="hit-hand-2-finger-basecover" />
            <body name="Right_Little_Phoaprox" pos="0 0 0" quat="0.707105 0.707108 0 0">
                <inertial pos="0.0621759 0.0443729 0.0787348" quat="0.821503 0.199145 -0.481905 0.230741" mass="1" diaginertia="1 1 1" />
                <joint name="Right_Little_2" pos="0 0 0" axis="0 0 1" limited="true" range="-0.5 1.4" damping="0.7" frictionloss="0.5" />
                <geom pos="0 0 0" type="mesh" mesh="hit-hand-2-finger-phaprox" />
                <body name="Right_Little_Phamed" pos="0.055 0 0">
                    <inertial pos="0 0 0" mass="1" diaginertia="1 1 1" />
                    <joint name="Right_Little_3" pos="0 0 0" axis="0 0 1" limited="true" range="-0.5 1.4" damping="0.7" frictionloss="0.5" />
                    <geom pos="0.01 0 0" type="mesh" mesh="hit-hand-2-finger-phamed" />
                    <body name="Right_Little_Phadist" pos="0.025 0 0" quat="0.707388 0 0 -0.706825">
                        <inertial pos="0 0 0" mass="1" diaginertia="1 1 1" />
                        <joint name="Right_Little_4" pos="0 0 0" axis="0 0 1" limited="true" range="-0.5 1.4" damping="0.7" frictionloss="0.5" />
                        <geom type="mesh" mesh="hit-hand-2-finger-phadist" />
                    </body>
                </body>
            </body>
        </body>
    </worldbody>
</mujoco>
